<?xml version="1.0"?>
<robot name="my_crp09" xmlns:xacro="http://ros.org/wiki/xacro">
  <!-- Include materials -->

  <xacro:property name="deg_to_rad" value="0.01745329251994329577"/>

  <!-- Constants -->
  <xacro:property name="M_SCALE" value="0.001 0.001 0.001"/> 
  <xacro:property name="M_PI" value="3.14159"/>

   <xacro:macro name="inertial_matrix" params="mass">
      <inertial>
      	<mass value="${mass}" />
        <inertia ixx="1.0" ixy="0.0" ixz="0.0" iyy="0.5" iyz="0.0" izz="1.0" />
      </inertial>
   </xacro:macro>

   <xacro:macro name="transmission_block" params="joint_name">
	  <transmission name="tran1">
	    <type>transmission_interface/SimpleTransmission</type>
	    <joint name="${joint_name}">
	      <hardwareInterface>hardware_interface/PositionJointInterface</hardwareInterface>
	    </joint>
	    <actuator name="motor1">
	      <hardwareInterface>hardware_interface/PositionJointInterface</hardwareInterface>
	      <mechanicalReduction>1</mechanicalReduction>
	    </actuator>
	  </transmission>
   </xacro:macro>


   <link name="base_link">  
    <visual>  
      <geometry>  
        <box size="1 0.75 0.05"/>  
    </geometry>  
    <origin rpy="0 0 1.57075" xyz="0 0 0.075"/>  
    <material name="blue">  
        <color rgba="0 0 .8 1"/>  
    </material>  
    </visual>  
    <collision>
      <origin rpy="0 0 1.57075" xyz="0 0 0.075"/>  
      <geometry>
	       <box size="1 0.75 0.05"/>  
      </geometry>
      </collision>>
</link>  

<link name="right_front_wheel">  
    <visual>  
      <geometry>  
        <cylinder length=".02" radius="0.075"/>  
      </geometry>  
      <material name="black">  
        <color rgba="0 0 0 1"/>  
      </material>  
    </visual>  
    <collision>
      <geometry>
	       <cylinder length=".02" radius="0.075"/>  
      </geometry>
      </collision>>
  </link>  

<joint name="right_front_wheel_joint" type="continuous">  
    <axis xyz="0 0 1"/>  
    <parent link="base_link"/>  
    <child link="right_front_wheel"/>  
    <origin rpy="0 1.57075 0" xyz="0.375 0.45 0.075"/>  
    <limit effort="100" velocity="100"/>  
    <joint_properties damping="0.0" friction="0.0"/>  
  </joint>  