<?xml version="1.0"?>  
<robot name="my_car">  

  <link name="base_link">  
    <visual>  
      <geometry>  
        <box size="1 0.75 0.05"/>  
    </geometry>  
    <origin rpy="0 0 1.57075" xyz="0 0 0.075"/>  
    <material name="blue">  
        <color rgba="0 0 .8 1"/>  
    </material>  
    </visual>  
    <collision>
      <geometry>
	       <box size="1 0.75 0.05"/>  
      </geometry>
      <origin rpy="0 0 1.57075" xyz="0 0 0.075"/>  
      </collision>
      <inertial>
	<mass value="1"/>
	<inertia ixx="1.0" ixy="0.0" ixz="0.0" iyy="1.0" iyz="0.0" izz="1.0"/>
    </inertial>
</link>  
 
<link name="right_front_wheel">  
    <visual>  
      <geometry>  
        <cylinder length=".02" radius="0.075"/>  
      </geometry>  
      <origin rpy="0 0 0" xyz="0 0 -0.01"/>
      <material name="black">  
        <color rgba="0 0 0 1"/>  
      </material>  
    </visual>  
    <collision>
      <geometry>
	       <cylinder length=".02" radius="0.075"/>  
      </geometry>
      <origin rpy="0 0 0" xyz="0 0 -0.01"/>
      </collision>
      <inertial>
	<mass value="1"/>
	<inertia ixx="1.0" ixy="0.0" ixz="0.0" iyy="1.0" iyz="0.0" izz="1.0"/>
    </inertial>
  </link>  
 
  <joint name="right_front_wheel_joint" type="continuous">  
    <axis xyz="0 0 1"/>  
    <parent link="base_link"/>  
    <child link="right_front_wheel"/>  
    <origin rpy="0 -1.57075 0" xyz="0.375 0.45 0.075"/>  
    <limit effort="100" velocity="100"/>  
    <joint_properties damping="0.0" friction="0.0"/>  
  </joint>  
 
  <link name="right_back_wheel">  
    <visual>  
      <geometry>  
        <cylinder length=".02" radius="0.075"/>  
      </geometry>  
      <origin rpy="0 0 0" xyz="0 0 -0.01"/>
      <material name="black">  
        <color rgba="0 0 0 1"/>  
      </material>  
    </visual>  
    <collision>
      <geometry>
	       <cylinder length=".02" radius="0.075"/>  
      </geometry>  
      <origin rpy="0 0 0" xyz="0 0 -0.01"/>
      </collision>
      <inertial>
	<mass value="1"/>
	<inertia ixx="1.0" ixy="0.0" ixz="0.0" iyy="1.0" iyz="0.0" izz="1.0"/>
    </inertial>
  </link>  
 
  <joint name="right_back_wheel_joint" type="continuous">  
    <axis xyz="0 0 1"/>  
    <parent link="base_link"/>  
    <child link="right_back_wheel"/>  
    <origin rpy="0 -1.57075 0" xyz="0.375 -0.45 0.075"/>  
    <limit effort="100" velocity="100"/>  
    <joint_properties damping="0.0" friction="0.0"/>  
</joint>  
 
<link name="left_front_wheel">  
    <visual>  
      <geometry>  
        <cylinder length=".02" radius="0.075"/>  
      </geometry>  
      <origin rpy="0 0 0" xyz="0 0 0.01"/>
      <material name="black">  
        <color rgba="0 0 0 1"/>  
      </material>  
    </visual>  
    <collision>
      <geometry>
	       <cylinder length=".02" radius="0.075"/>  
      </geometry>  
      <origin rpy="0 0 0" xyz="0 0 0.01"/>
      </collision>
      <inertial>
	<mass value="1"/>
	<inertia ixx="1.0" ixy="0.0" ixz="0.0" iyy="1.0" iyz="0.0" izz="1.0"/>
    </inertial>
  </link>  
 
  <joint name="left_front_wheel_joint" type="continuous">  
    <axis xyz="0 0 1"/>  
    <parent link="base_link"/>  
    <child link="left_front_wheel"/>  
    <origin rpy="0 -1.57075 0" xyz="-0.375 0.45 0.075"/>  
    <limit effort="100" velocity="100"/>  
    <joint_properties damping="0.0" friction="0.0"/>  
  </joint>  
 
  <link name="left_back_wheel">  
    <visual>  
      <geometry>  
        <cylinder length=".02" radius="0.075"/>  
      </geometry>  
      <origin rpy="0 0 0" xyz="0 0 0.01"/>
      <material name="black">  
        <color rgba="0 0 0 1"/>  
      </material>  
    </visual>  
     <collision>
      <geometry>
	       <cylinder length=".02" radius="0.075"/>  
      </geometry>  
      <origin rpy="0 0 0" xyz="0 0 0.01"/>
      </collision>
      <inertial>
	<mass value="1"/>
	<inertia ixx="1.0" ixy="0.0" ixz="0.0" iyy="1.0" iyz="0.0" izz="1.0"/>
    </inertial>
  </link>  
 
  <joint name="left_back_wheel_joint" type="continuous">  
    <axis xyz="0 0 1"/>  
    <parent link="base_link"/>  
    <child link="left_back_wheel"/>  
    <origin rpy="0 -1.57075 0" xyz="-0.375 -0.45 0.075"/>  
    <limit effort="100" velocity="100"/>  
    <joint_properties damping="0.0" friction="0.0"/>  
  </joint>  
</robot> 
