<?xml version="1.0"?>  
<robot name="my_car">  

  <link name="base_link">  
    <visual>  
      <geometry>  
        <box size="1 0.75 0.05"/>  
    </geometry>  
    <origin rpy="0 0 1.57075" xyz="0 0 0.1"/>  
    <material name="blue">  
        <color rgba="0 0 .8 1"/>  
    </material>  
    </visual>  
    <collision>
      <geometry>
	       <box size="1 0.75 0.05"/>  
      </geometry>
      <origin rpy="0 0 1.57075" xyz="0 0 0.1"/>  
      </collision>
      <inertial>
	<mass value="1"/>
	<inertia ixx="1.0" ixy="0.0" ixz="0.0" iyy="1.0" iyz="0.0" izz="1.0"/>
    </inertial>
</link>  
<gazebo reference="base_link">
    <material>Gazebo/White</material>
    <turnGravityOff>false</turnGravityOff>
  </gazebo>
 
  <link name="right_back_wheel">  
    <visual>  
      <geometry>  
        <cylinder length=".02" radius="0.1"/>  
      </geometry>  
      <origin rpy="0 0 0" xyz="0 0 -0.01"/>
      <material name="black">  
        <color rgba="0 0 0 1"/>  
      </material>  
    </visual>  
    <collision>
      <geometry>
	       <cylinder length=".02" radius="0.1"/>  
      </geometry>  
      <origin rpy="0 0 0" xyz="0 0 -0.01"/>
      </collision>
      <inertial>
	<mass value="1"/>
	<inertia ixx="1.0" ixy="0.0" ixz="0.0" iyy="1.0" iyz="0.0" izz="1.0"/>
    </inertial>
  </link>  
  <gazebo reference="right_back_wheel">
    <mu1 value="1.0"/>
    <mu2 value="1.0"/>
    <kp value="10000000.0"/>
    <kd value="1.0"/>
    <fdir1 value="1 0 0"/>
    <material>Gazebo/Grey</material>
    <turnGravityOff>false</turnGravityOff>
  </gazebo>

  <joint name="right_back_wheel_joint" type="continuous">  
    <axis xyz="0 0 1"/>  
    <parent link="base_link"/>  
    <child link="right_back_wheel"/>  
    <origin rpy="0 -1.57075 0" xyz="0.375 -0.45 0.1"/>  
    <limit effort="100" velocity="100"/>  
    <joint_properties damping="0.0" friction="0.0"/>  
</joint>  
  <transmission name="right_back_wheel_joint_trans">
    <type>transmission_interface/SimpleTransmission</type>
    <joint name="right_back_wheel_joint"/>
    <actuator name="right_back_wheel_joint_motor">
      <hardwareInterface>EffortJointInterface</hardwareInterface>
      <mechanicalReduction>1</mechanicalReduction>
    </actuator>
  </transmission>
 
<link name="caster_wheel">  
    <visual>  
      <geometry>  
        <cylinder length=".02" radius="0.0375"/>  
      </geometry>  
      <origin rpy="0 0 0" xyz="0 0 0"/>
      <material name="black">  
        <color rgba="0 0 0 1"/>  
      </material>  
    </visual>  
    <collision>
      <geometry>
	       <cylinder length=".02" radius="0.0375"/>  
      </geometry>  
      <origin rpy="0 0 0" xyz="0 0 0.01"/>
      </collision>
      <inertial>
	<mass value="1"/>
	<inertia ixx="1.0" ixy="0.0" ixz="0.0" iyy="1.0" iyz="0.0" izz="1.0"/>
    </inertial>
  </link>  
  <gazebo reference="caster_wheel">
    <mu1 value="1.0"/>
    <mu2 value="1.0"/>
    <kp value="10000000.0"/>
    <kd value="1.0"/>
    <fdir1 value="1 0 0"/>
    <material>Gazebo/Grey</material>
    <turnGravityOff>false</turnGravityOff>
  </gazebo>

  <joint name="caster_wheel_joint" type="fixed">  
    <parent link="base_link"/>  
    <child link="caster_wheel"/>  
    <origin rpy="0 -1.57075 0" xyz="0 0.45 0.0375"/>  
  </joint>  
 <gazebo reference="caster_wheel_joint">
    <turnGravityOff>false</turnGravityOff>
  </gazebo>
 
  <link name="left_back_wheel">  
    <visual>  
      <geometry>  
        <cylinder length=".02" radius="0.1"/>  
      </geometry>  
      <origin rpy="0 0 0" xyz="0 0 0.01"/>
      <material name="black">  
        <color rgba="0 0 0 1"/>  
      </material>  
    </visual>  
     <collision>
      <geometry>
	       <cylinder length=".02" radius="0.1"/>  
      </geometry>  
      <origin rpy="0 0 0" xyz="0 0 0.01"/>
      </collision>
      <inertial>
	<mass value="1"/>
	<inertia ixx="1.0" ixy="0.0" ixz="0.0" iyy="1.0" iyz="0.0" izz="1.0"/>
    </inertial>
  </link>  
  <gazebo reference="left_back_wheel">
    <mu1 value="1.0"/>
    <mu2 value="1.0"/>
    <kp value="10000000.0"/>
    <kd value="1.0"/>
    <fdir1 value="1 0 0"/>
    <material>Gazebo/Grey</material>
    <turnGravityOff>false</turnGravityOff>
  </gazebo>
  
  <joint name="left_back_wheel_joint" type="continuous">  
    <axis xyz="0 0 1"/>  
    <parent link="base_link"/>  
    <child link="left_back_wheel"/>  
    <origin rpy="0 -1.57075 0" xyz="-0.375 -0.45 0.1"/>  
    <limit effort="100" velocity="100"/>  
    <joint_properties damping="0.0" friction="0.0"/>  
  </joint>  
    <transmission name="left_back_wheel_joint_trans">
    <type>transmission_interface/SimpleTransmission</type>
    <joint name="left_back_wheel_joint"/>
    <actuator name="left_back_wheel_joint_motor">
      <hardwareInterface>EffortJointInterface</hardwareInterface>
      <mechanicalReduction>1</mechanicalReduction>
    </actuator>
  </transmission>

 <!-- SENSORS -->
  <!-- hokuyo -->
  <link name="hokuyo_link">
    <visual>
      <origin rpy="0 0 0" xyz="0 0 0.025"/>
      <geometry>
        <box size="0.05 0.05 0.05"/>
      </geometry>
      <material name="Blue"/>
    </visual>
  </link>

  <joint name="hokuyo_joint" type="fixed">
    <origin rpy="0 0 0" xyz="0 0.45 0.125"/>
    <parent link="base_link"/>
    <child link="hokuyo_link"/>
  </joint>

  <gazebo reference="hokuyo_link">
    <material>Gazebo/Blue</material>
    <turnGravityOff>false</turnGravityOff>
    <sensor name="head_hokuyo_sensor" type="ray">
      <pose>0.025 0 0 0 0 0</pose>
      <visualize>false</visualize>
      <update_rate>40</update_rate>
      <ray>
        <scan>
          <horizontal>
            <samples>720</samples>
            <resolution>1</resolution>
            <min_angle>-1.570796</min_angle>
            <max_angle>1.570796</max_angle>
          </horizontal>
        </scan>
        <range>
          <min>0.10</min>
          <max>10.0</max>
          <resolution>0.001</resolution>
        </range>
      </ray>
      <plugin filename="libgazebo_ros_laser.so" name="gazebo_ros_head_hokuyo_controller">
        <topicName>/scan</topicName>
        <frameName>hokuyo_link</frameName>
      </plugin>
    </sensor>
  </gazebo>

   <gazebo>
    <plugin filename="libgazebo_ros_diff_drive.so" name="my_car_controller_front">
      <rosDebugLevel>Debug</rosDebugLevel>
      <publishWheelTF>True</publishWheelTF>
      <publishTf>1</publishTf>
      <publishWheelJointState>true</publishWheelJointState>
      <alwaysOn>true</alwaysOn>
      <updateRate>100.0</updateRate>
      <leftJoint>left_back_wheel_joint</leftJoint>
      <rightJoint>right_back_wheel_joint</rightJoint>
      <wheelSeparation>0.3</wheelSeparation>
      <wheelDiameter>0.08</wheelDiameter>
      <broadcastTF>1</broadcastTF>
      <wheelTorque>30</wheelTorque>
      <wheelAcceleration>1.8</wheelAcceleration>
      <commandTopic>cmd_vel</commandTopic>
      <odometryFrame>odom</odometryFrame>
      <odometryTopic>odom</odometryTopic>
      <robotBaseFrame>base_link</robotBaseFrame>
    </plugin>
  </gazebo>

</robot> 
