<?xml version="1.0"?>
<robot name="crp09">

  <link name="base_link">

    <visual>
      <geometry>
	<cylinder length="0.25" radius="0.1125"/>
      </geometry>
      <origin rpy="0 0 0" xyz="0 0 0.125"/>
      <material name="yellow">
        <color rgba="1 1 0 1"/>
      </material>
    </visual>

    <collision>
      <geometry>
	<cylinder length="0.25" radius="0.1125"/>
      </geometry>
      <origin rpy="0 0 0" xyz="0 0 0.125"/>
    </collision>

    <inertial>
	<mass value="1"/>
	<inertia ixx="1.0" ixy="0.0" ixz="0.0" iyy="1.0" iyz="0.0" izz="1.0"/>
    </inertial>
  </link>

  <joint name="joint1" type="revolute">
    <parent link="base_link"/>
    <child link="link1"/>
    <origin xyz="0 0 0.25"/>
    <axis xyz="0 0 1" />
    <limit effort="300" velocity="0.1" lower="-2.96" upper="2.96"/>
    <dynamics damping="50" friction="1"/>
  </joint>

  <link name="link1">
    <visual>
      <geometry>
	<cylinder length="0.171" radius="0.1125"/>
      </geometry>
      <origin rpy="0 0 0" xyz="0 0 0.0855"/>
      <material name="red">
        <color rgba="0 0 1 1"/>
      </material>
    </visual>

    <collision>
      <geometry>
	<cylinder length="0.171" radius="0.1125"/>
      </geometry>
      <origin rpy="0 0 0" xyz="0 0 0.0855"/>
    </collision>

    <inertial>
	<mass value="1"/>
	<inertia ixx="1.0" ixy="0.0" ixz="0.0" iyy="1.0" iyz="0.0" izz="1.0"/>
    </inertial>
  </link>

  <joint name="joint2" type="revolute">
    <parent link="link1"/>
    <child link="link2"/>
    <origin xyz="0 0 0.171"/>
    <axis xyz="1 0 0" />
    <limit effort="300" velocity="0.1" lower="-2.355" upper="1.74"/>
    <dynamics damping="50" friction="1"/>
  </joint>

  <link name="link2">
    <visual>
      <geometry>
	<cylinder length="0.455" radius="0.1"/>
      </geometry>
      <origin rpy="0 0 0" xyz="0 0 0.2275"/>
      <material name="yellow">
        <color rgba="1 1 0 1"/>
      </material>
    </visual>

    <collision>
      <geometry>
	<cylinder length="0.455" radius="0.1"/>
      </geometry>
      <origin rpy="0 0 0" xyz="0 0 0.2275"/>
    </collision>

    <inertial>
	<mass value="1"/>
	<inertia ixx="1.0" ixy="0.0" ixz="0.0" iyy="1.0" iyz="0.0" izz="1.0"/>
    </inertial>
  </link>

    <joint name="joint3" type="revolute">
    <parent link="link2"/>
    <child link="link3"/>
    <origin xyz="0 0 0.455"/>
    <axis xyz="1 0 0" />
    <limit effort="300" velocity="0.1" lower="-1.13" upper="3.05"/>
    <dynamics damping="50" friction="1"/>
  </joint>

    <link name="link3">
    <visual>
      <geometry>
	<cylinder length="0.15" radius="0.04"/>
      </geometry>
      <origin rpy="-1.57 0 0" xyz="0 0.075 0"/>
      <material name="red">
        <color rgba="0 0 1 1"/>
      </material>
    </visual>

    <collision>
      <geometry>
	<cylinder length="0.15" radius="0.04"/>
      </geometry>
      <origin rpy="-1.57 0 0" xyz="0 0.075 0"/>
    </collision>

    <inertial>
	<mass value="1"/>
	<inertia ixx="1.0" ixy="0.0" ixz="0.0" iyy="1.0" iyz="0.0" izz="1.0"/>
    </inertial>
  </link>
  
    <joint name="joint4" type="revolute">
    <parent link="link3"/>
    <child link="link4"/>
    <origin xyz="0 0.15 0"/>
    <axis xyz="0 1 0" />
    <limit effort="300" velocity="0.1" lower="-2.96" upper="2.96"/>
    <dynamics damping="50" friction="1"/>
  </joint>

      <link name="link4">
    <visual>
      <geometry>
	<cylinder length="0.29" radius="0.04"/>
      </geometry>
      <origin rpy="-1.57 0 0" xyz="0 0.145 0"/>
      <material name="yellow">
        <color rgba="1 1 0 1"/>
      </material>
    </visual>

    <collision>
      <geometry>
	<cylinder length="0.29" radius="0.04"/>
      </geometry>
      <origin rpy="-1.57 0 0" xyz="0 0.145 0"/>
    </collision>

    <inertial>
	<mass value="1"/>
	<inertia ixx="1.0" ixy="0.0" ixz="0.0" iyy="1.0" iyz="0.0" izz="1.0"/>
    </inertial>
  </link>

    <joint name="joint5" type="revolute">
    <parent link="link4"/>
    <child link="link5"/>
    <origin xyz="0 0.29 0"/>
    <axis xyz="1 0 0" />
    <limit effort="300" velocity="0.1" lower="-2.093" upper="2.093"/>
    <dynamics damping="50" friction="1"/>
  </joint>

   <link name="link5">
    <visual>
      <geometry>
	<cylinder length="0.105" radius="0.04"/>
      </geometry>
      <origin rpy="-1.57 0 0" xyz="0 0.0525 0"/>
      <material name="red">
        <color rgba="0 0 1 1"/>
      </material>
    </visual>

    <collision>
      <geometry>
	<cylinder length="0.105" radius="0.04"/>
      </geometry>
      <origin rpy="-1.57 0 0" xyz="0 0.0525 0"/>
    </collision>

    <inertial>
	<mass value="1"/>
	<inertia ixx="1.0" ixy="0.0" ixz="0.0" iyy="1.0" iyz="0.0" izz="1.0"/>
    </inertial>
  </link>

  <joint name="joint6" type="revolute">
    <parent link="link5"/>
    <child link="link_tool"/>
    <origin xyz="0 0.105 0"/>
    <axis xyz="0 1 0" />
    <limit effort="300" velocity="0.1" lower="-3.14" upper="3.14"/>
    <dynamics damping="50" friction="1"/>
  </joint>

<!--tool-->
  <link name="link_tool">
    <visual>
      <geometry>
	<cylinder length="0.02" radius="0.035"/>
      </geometry>
      <origin rpy="-1.57 0 0" xyz="0 0.01 0"/>
      <material name="yellow">
        <color rgba="1 1 0 1"/>
      </material>
    </visual>

    <collision>
      <geometry>
	<cylinder length="0.02" radius="0.035"/>
      </geometry>
      <origin rpy="-1.57 0 0" xyz="0 0.01 0"/>
    </collision>

    <inertial>
	<mass value="1"/>
	<inertia ixx="1.0" ixy="0.0" ixz="0.0" iyy="1.0" iyz="0.0" izz="1.0"/>
    </inertial>
  </link>

  <joint name="finger_joint1" type="prismatic">
    <parent link="link_tool"/>
    <child link="gripper_finger1"/>
    <origin xyz="0 0.02 0.035"/>
    <axis xyz="0 0 1" />
    <limit effort="300" velocity="0.1" lower="-0.03" upper="0"/>
    <dynamics damping="50" friction="1"/>
  </joint>

  <link name="gripper_finger1">
    <visual>
      <geometry>
	<box size="0.01 0.01 0.04"/>
      </geometry>
      <origin rpy="-1.57 0 0" xyz="0 0.02 0"/>
      <material name="red">
        <color rgba="0 0 1 1"/>
      </material>
    </visual>

    <collision>
      <geometry>
	<box size="0.01 0.01 0.04"/>
      </geometry>
      <origin rpy="-1.57 0 0" xyz="0 0.02 0"/>
    </collision>

    <inertial>
	<mass value="1"/>
	<inertia ixx="1.0" ixy="0.0" ixz="0.0" iyy="1.0" iyz="0.0" izz="1.0"/>
    </inertial>
  </link>

  <joint name="finger_joint2" type="prismatic">
    <parent link="link_tool"/>
    <child link="gripper_finger2"/>
    <origin xyz="0 0.02 -0.035"/>
    <axis xyz="0 0 1" />
    <limit effort="300" velocity="0.1" lower="0" upper="0.03"/>
    <dynamics damping="50" friction="1"/>
  </joint>

  <link name="gripper_finger2">
    <visual>
      <geometry>
	<box size="0.01 0.01 0.04"/>
      </geometry>
      <origin rpy="-1.57 0 0" xyz="0 0.02 0"/>
      <material name="red">
        <color rgba="0 0 1 1"/>
      </material>
    </visual>

    <collision>
      <geometry>
	<box size="0.01 0.01 0.04"/>
      </geometry>
      <origin rpy="-1.57 0 0" xyz="0 0.02 0"/>
    </collision>

    <inertial>
	<mass value="1"/>
	<inertia ixx="1.0" ixy="0.0" ixz="0.0" iyy="1.0" iyz="0.0" izz="1.0"/>
    </inertial>
  </link>
</robot>
