<?xml version="1.0"?>
<robot name="my_crp09" xmlns:xacro="http://ros.org/wiki/xacro">
  <!-- Include materials -->

    <material name="Black">
        <color rgba="0.0 0.0 0.0 1.0"/>
    </material>

    <material name="Red">
        <color rgba="0.8 0.0 0.0 1.0"/>
    </material>

    <material name="White">
        <color rgba="1.0 1.0 1.0 1.0"/>
    </material>


  <xacro:property name="deg_to_rad" value="0.01745329251994329577"/>

  <!-- Constants -->
  <xacro:property name="M_SCALE" value="0.001 0.001 0.001"/> 
  <xacro:property name="M_PI" value="3.14159"/>

   <xacro:macro name="inertial_matrix" params="mass">
      <inertial>
      	<mass value="${mass}" />
        <inertia ixx="1.0" ixy="0.0" ixz="0.0" iyy="0.5" iyz="0.0" izz="1.0" />
      </inertial>
   </xacro:macro>

   <xacro:macro name="transmission_block" params="joint_name">
	  <transmission name="tran1">
	    <type>transmission_interface/SimpleTransmission</type>
	    <joint name="${joint_name}">
	      <hardwareInterface>hardware_interface/PositionJointInterface</hardwareInterface>
	    </joint>
	    <actuator name="motor1">
	      <hardwareInterface>hardware_interface/PositionJointInterface</hardwareInterface>
	      <mechanicalReduction>1</mechanicalReduction>
	    </actuator>
	  </transmission>
   </xacro:macro>

<!-- BOTTOM FIXED LINK 
This link is the base of the arm in which arm is placed 
-->

<!-- ///////////////////////////////////////////////////////////////////////////////////////////////////////////////////// -->

  <joint name="bottom_joint" type="fixed">
    <origin xyz="0 0 0" rpy="0 0 0" />
    <parent link="base_link"/>
    <child link="bottom_link"/>
  </joint>

  <link name="bottom_link">

    <visual>
      <origin xyz=" 0 0 -0.01"  rpy="0 0 0"/>
      <geometry>

	       <box size="1 1 0.02" />

      </geometry>
      <material name="Brown" />
    </visual>

    <collision>
      <origin xyz=" 0 0 -0.01"  rpy="0 0 0"/>
      <geometry>
	       <box size="1 1 0.02" />
      </geometry>
      </collision>>

  </link>

  <gazebo reference="bottom_link">
    <material>Gazebo/Red</material>
  </gazebo>

  <link name="base_link">

    <visual>
      <geometry>
	<cylinder length="0.25" radius="0.1125"/>
      </geometry>
      <origin rpy="0 0 0" xyz="0 0 0.125"/>
      <material name="yellow">
        <color rgba="1 1 0 1"/>
      </material>
    </visual>

    <collision>
      <geometry>
	<cylinder length="0.25" radius="0.1125"/>
      </geometry>
      <origin rpy="0 0 0" xyz="0 0 0.125"/>
    </collision>

    <inertial>
	<mass value="1"/>
	<inertia ixx="1.0" ixy="0.0" ixz="0.0" iyy="1.0" iyz="0.0" izz="1.0"/>
    </inertial>

  <gazebo reference="base_link">
    <material>Gazebo/White</material>
  </gazebo>
  </link>

  <joint name="joint1" type="revolute">
    <parent link="base_link"/>
    <child link="link1"/>
    <origin xyz="0 0 0.25"/>
    <axis xyz="0 0 1" />
    <limit effort="300" velocity="0.1" lower="-2.96" upper="2.96"/>
    <dynamics damping="50" friction="1"/>
  </joint>

  <link name="link1">
    <visual>
      <geometry>
	<cylinder length="0.171" radius="0.1125"/>
      </geometry>
      <origin rpy="0 0 0" xyz="0 0 0.0855"/>
      <material name="red">
        <color rgba="0 0 1 1"/>
      </material>
    </visual>

    <collision>
      <geometry>
	<cylinder length="0.171" radius="0.1125"/>
      </geometry>
      <origin rpy="0 0 0" xyz="0 0 0.0855"/>
    </collision>

    <inertial>
	<mass value="1"/>
	<inertia ixx="1.0" ixy="0.0" ixz="0.0" iyy="1.0" iyz="0.0" izz="1.0"/>
    </inertial>
  <gazebo reference="link1">
    <material>Gazebo/Red</material>
  </gazebo>
  </link>

  <joint name="joint2" type="revolute">
    <parent link="link1"/>
    <child link="link2"/>
    <origin xyz="0 0 0.171"/>
    <axis xyz="1 0 0" />
    <limit effort="300" velocity="0.1" lower="-2.355" upper="1.74"/>
    <dynamics damping="50" friction="1"/>
  </joint>

  <link name="link2">
    <visual>
      <geometry>
	<cylinder length="0.455" radius="0.1"/>
      </geometry>
      <origin rpy="0 0 0" xyz="0 0 0.2275"/>
      <material name="yellow">
        <color rgba="1 1 0 1"/>
      </material>
    </visual>

    <collision>
      <geometry>
	<cylinder length="0.455" radius="0.1"/>
      </geometry>
      <origin rpy="0 0 0" xyz="0 0 0.2275"/>
    </collision>

    <inertial>
	<mass value="1"/>
	<inertia ixx="1.0" ixy="0.0" ixz="0.0" iyy="1.0" iyz="0.0" izz="1.0"/>
    </inertial>
  <gazebo reference="link2">
    <material>Gazebo/White</material>
  </gazebo>
  </link>

    <joint name="joint3" type="revolute">
    <parent link="link2"/>
    <child link="link3"/>
    <origin xyz="0 0 0.455"/>
    <axis xyz="1 0 0" />
    <limit effort="300" velocity="0.1" lower="-1.13" upper="3.05"/>
    <dynamics damping="50" friction="1"/>
  </joint>

    <link name="link3">
    <visual>
      <geometry>
	<cylinder length="0.15" radius="0.04"/>
      </geometry>
      <origin rpy="-1.57 0 0" xyz="0 0.075 0"/>
      <material name="red">
        <color rgba="0 0 1 1"/>
      </material>
    </visual>

    <collision>
      <geometry>
	<cylinder length="0.15" radius="0.04"/>
      </geometry>
      <origin rpy="-1.57 0 0" xyz="0 0.075 0"/>
    </collision>

    <inertial>
	<mass value="1"/>
	<inertia ixx="1.0" ixy="0.0" ixz="0.0" iyy="1.0" iyz="0.0" izz="1.0"/>
    </inertial>

  <gazebo reference="link3">
    <material>Gazebo/Red</material>
  </gazebo>
  </link>
  
    <joint name="joint4" type="revolute">
    <parent link="link3"/>
    <child link="link4"/>
    <origin xyz="0 0.15 0"/>
    <axis xyz="0 1 0" />
    <limit effort="300" velocity="0.1" lower="-2.96" upper="2.96"/>
    <dynamics damping="50" friction="1"/>
  </joint>

      <link name="link4">
    <visual>
      <geometry>
	<cylinder length="0.29" radius="0.04"/>
      </geometry>
      <origin rpy="-1.57 0 0" xyz="0 0.145 0"/>
      <material name="yellow">
        <color rgba="1 1 0 1"/>
      </material>
    </visual>

    <collision>
      <geometry>
	<cylinder length="0.29" radius="0.04"/>
      </geometry>
      <origin rpy="-1.57 0 0" xyz="0 0.145 0"/>
    </collision>

    <inertial>
	<mass value="1"/>
	<inertia ixx="1.0" ixy="0.0" ixz="0.0" iyy="1.0" iyz="0.0" izz="1.0"/>
    </inertial>

  <gazebo reference="link4">
    <material>Gazebo/White</material>
  </gazebo>
  </link>

    <joint name="joint5" type="revolute">
    <parent link="link4"/>
    <child link="link5"/>
    <origin xyz="0 0.29 0"/>
    <axis xyz="1 0 0" />
    <limit effort="300" velocity="0.1" lower="-2.093" upper="2.093"/>
    <dynamics damping="50" friction="1"/>
  </joint>

   <link name="link5">
    <visual>
      <geometry>
	<cylinder length="0.105" radius="0.04"/>
      </geometry>
      <origin rpy="-1.57 0 0" xyz="0 0.0525 0"/>
      <material name="red">
        <color rgba="0 0 1 1"/>
      </material>
    </visual>

    <collision>
      <geometry>
	<cylinder length="0.105" radius="0.04"/>
      </geometry>
      <origin rpy="-1.57 0 0" xyz="0 0.0525 0"/>
    </collision>

    <inertial>
	<mass value="1"/>
	<inertia ixx="1.0" ixy="0.0" ixz="0.0" iyy="1.0" iyz="0.0" izz="1.0"/>
    </inertial>

  <gazebo reference="link5">
    <material>Gazebo/Red</material>
  </gazebo>
  </link>

  <joint name="joint6" type="revolute">
    <parent link="link5"/>
    <child link="link_tool"/>
    <origin xyz="0 0.105 0"/>
    <axis xyz="0 1 0" />
    <limit effort="300" velocity="0.1" lower="-3.14" upper="3.14"/>
    <dynamics damping="50" friction="1"/>
  </joint>

<!--tool-->
  <link name="link_tool">
    <visual>
      <geometry>
	<cylinder length="0.02" radius="0.035"/>
      </geometry>
      <origin rpy="-1.57 0 0" xyz="0 0.01 0"/>
      <material name="yellow">
        <color rgba="1 1 0 1"/>
      </material>
    </visual>

    <collision>
      <geometry>
	<cylinder length="0.02" radius="0.035"/>
      </geometry>
      <origin rpy="-1.57 0 0" xyz="0 0.01 0"/>
    </collision>

    <inertial>
	<mass value="1"/>
	<inertia ixx="1.0" ixy="0.0" ixz="0.0" iyy="1.0" iyz="0.0" izz="1.0"/>
    </inertial>

  <gazebo reference="link_tool">
    <material>Gazebo/White</material>
  </gazebo>
  </link>

  <joint name="finger_joint1" type="prismatic">
    <parent link="link_tool"/>
    <child link="gripper_finger1"/>
    <origin xyz="0 0.02 0.035"/>
    <axis xyz="0 0 1" />
    <limit effort="300" velocity="0.1" lower="-0.03" upper="0"/>
    <dynamics damping="50" friction="1"/>
  </joint>

  <link name="gripper_finger1">
    <visual>
      <geometry>
	<box size="0.01 0.01 0.04"/>
      </geometry>
      <origin rpy="-1.57 0 0" xyz="0 0.02 0"/>
      <material name="red">
        <color rgba="0 0 1 1"/>
      </material>
    </visual>

    <collision>
      <geometry>
	<box size="0.01 0.01 0.04"/>
      </geometry>
      <origin rpy="-1.57 0 0" xyz="0 0.02 0"/>
    </collision>

    <inertial>
	<mass value="1"/>
	<inertia ixx="1.0" ixy="0.0" ixz="0.0" iyy="1.0" iyz="0.0" izz="1.0"/>
    </inertial>

  <gazebo reference="gripper_finger1">
    <material>Gazebo/White</material>
  </gazebo>
  </link>

  <joint name="finger_joint2" type="prismatic">
    <parent link="link_tool"/>
    <child link="gripper_finger2"/>
    <origin xyz="0 0.02 -0.035"/>
    <axis xyz="0 0 1" />
    <limit effort="300" velocity="0.1" lower="0" upper="0.03"/>
    <dynamics damping="50" friction="1"/>
  </joint>

  <link name="gripper_finger2">
    <visual>
      <geometry>
	<box size="0.01 0.01 0.04"/>
      </geometry>
      <origin rpy="-1.57 0 0" xyz="0 0.02 0"/>
      <material name="red">
        <color rgba="0 0 1 1"/>
      </material>
    </visual>

    <collision>
      <geometry>
	<box size="0.01 0.01 0.04"/>
      </geometry>
      <origin rpy="-1.57 0 0" xyz="0 0.02 0"/>
    </collision>

    <inertial>
	<mass value="1"/>
	<inertia ixx="1.0" ixy="0.0" ixz="0.0" iyy="1.0" iyz="0.0" izz="1.0"/>
    </inertial>

  <gazebo reference="gripper_finger2">
    <material>Gazebo/White</material>
  </gazebo>

  </link>



<!-- ///////////////////////////////////////////////////////////////////////////////////////////////////////////////////// -->
  <!-- Transmissions for ROS Control -->

   <xacro:transmission_block joint_name="joint1"/>
   <xacro:transmission_block joint_name="joint2"/>
   <xacro:transmission_block joint_name="joint3"/>
   <xacro:transmission_block joint_name="joint4"/>
   <xacro:transmission_block joint_name="joint5"/>
   <xacro:transmission_block joint_name="joint6"/>
   <xacro:transmission_block joint_name="finger_joint1"/>
   <xacro:transmission_block joint_name="finger_joint2"/>
	
 <!-- ros_control plugin -->
  <gazebo>
    <plugin name="gazebo_ros_control" filename="libgazebo_ros_control.so">
      <robotNamespace>/my_crp09</robotNamespace>
    </plugin>
  </gazebo>




</robot>
